<mujoco>
	<option timestep="0.01" integrator="RK4" gravity="0 0 -9.81">
		<!-- <flag sensornoise="enable" energy="enable" contact="disable" /> -->
		<flag energy="enable" contact="enable" />
	</option>
	
	<asset>
		<texture name="grid" type="2d" builtin="checker" width="512" height="512" rgb1=".9 .9 .9" rgb2=".1 .1 .1"/>
		<material name="grid" texture="grid" texrepeat="10 10" texuniform="true" reflectance=".2"/>
		
		<mesh name="tetrahedron" vertex="0 0 0  1 0 0  0 1 0  0 0 0.3"/>
	</asset>
	
	<worldbody>
        <light diffuse=".5 .5 .5" pos="0 0 3" dir="0 0 -1"/>
		<!-- <geom type="plane" size="1 1 0.1" rgba=".9 0 0 1"/> -->
		
		<geom type="plane" size="1 1 0.1" material="grid"/>
		
		<geom type="mesh" mesh="tetrahedron" pos="2 0 0" euler="0 0 135" rgba="1 0 0 1" />
		
		<!-- Begin chassis -->
		<body name="chassis" pos="0 0 0" euler="0 0 0">
			<!-- <freejoint/> -->
			<joint type="free"/>
			<geom type="box" size="0.25 0.2 0.05" rgba="0 0.9 0 1" mass="30"/>
			<site name="chassis_frame" pos="0 0 0" size="0.01" />
			<site name="rangefinder_frame" pos=".3 0 0" euler="0 90 0" size="0.01" /> 
			<!-- Rangefinders measure along the Z axis... rotate so that it does not point infinite space! -->
			
			<!-- Begin right wheel -->
			<body name = "wheel_r" pos="0 -0.26 0" euler="-90 0 0">
				<joint name="wheel_r_axis" type="hinge" axis = "0 0 1" pos="0 0 -0.0" damping=".03"/>
				<geom type="cylinder" size="0.1 0.05" rgba=".5 .5 .5 1" mass="1"/>
				<!-- <site name="end_effector" pos="0 0 0.5" size="0.1" /> -->
			</body>

			<!-- Begin left wheel -->
			<body name = "wheel_l" pos="0 0.26 0" euler="-90 0 0">
				<joint name="wheel_l_axis" type="hinge" axis = "0 0 1" pos="0 0 -0.0" damping=".03"/>
				<geom type="cylinder" size="0.1 0.05" rgba=".5 .5 .5 1" mass="1"/>
				<!-- <site name="end_effector" pos="0 0 0.5" size="0.1" /> -->
			</body>

			<!-- Rear "caster" wheel -->
			<geom name="sphere_wheel" pos="-0.25 0 -0.05" type="sphere" size=".05" condim="1" priority="1"/>
			
		</body>
	</worldbody>
	<!-- Actuators:
	https://mujoco.readthedocs.io/en/stable/XMLreference.html#actuator -->
	<actuator>
		<motor    name="torque_wheel_r" joint="wheel_r_axis" gear="1" ctrllimited="true" ctrlrange="-10 10"/>

		<motor    name="torque_wheel_l" joint="wheel_l_axis" gear="1" ctrllimited="true" ctrlrange="-10 10"/>
	</actuator>

	<!-- Sensors https://mujoco.readthedocs.io/en/stable/XMLreference.html#sensor -->
	<sensor>
		<framepos  objtype="site" objname="chassis_frame" />
		<velocimeter name="sensor_vel" site="chassis_frame" />
		<accelerometer name="sensor_accel" site="chassis_frame" />
		<gyro name="sensor_gyro" site="chassis_frame" noise="0"/>
		
		<rangefinder site="rangefinder_frame" noise="0" />
	</sensor>
	
	<!--
	<actuator>
		<motor    name="torque1" joint="pin" gear="1" ctrllimited="true" ctrlrange="-100 100"/>
		<position name="pservo1" joint="pin" kp="100" />
		<velocity name="vservo1" joint="pin" kv="10" />
		
		<motor    name="torque2" joint="pin2" gear="1" ctrllimited="true" ctrlrange="-100 100"/>
		<position name="pservo2" joint="pin2" kp="100" />
		<velocity name="vservo2" joint="pin2" kv="10" />
	</actuator>
	
	<sensor>
		<framepos  objtype='site' objname="end_effector" />
		<framelinvel  objtype='site' objname="end_effector" />
		<jointpos name = 'q1_sensor' joint = 'pin'  noise = '0' />
		<jointpos name = 'q2_sensor' joint = 'pin2' noise = '0' />
	</sensor>
	-->
	
</mujoco>

